Workbook
Name ID: Subcontractors!$A$1
Name ID: #REF!
Name InteracEmail: #REF!
Name Name: Table4[[#Headers],[Name]]
Name Name: #REF!
Name PhoneNumber: Table4[[#Headers],[Phone Number]]
Name PhoneNumber: #REF!
Name PhysicalAddress: Table4[[#Headers],[Physical Address]]
Name PhysicalAddress: #REF!
Name Worker_Name: Table4[[#Headers],[Name]]
Name Worker_Name: #REF!
Name WorkerAlias: Table4[[#Headers],[Alias]]
Name WorkerAlias: #REF!
Name WorkerComment: Subcontractors!$G$1
Name WorkerComment: #REF!
Name WorkerName: Table4[[#Headers],[Name]]
Name WorkerName: #REF!

Sheet DRAFT
A2: 46032 | C2: Date | D2: Hyatt | E2: Hrs | G2: Date | H2: Burlington | I2: Hrs | K2: Date | L2: Oshawa | M2: Hrs | O2: Date | P2: 290 Derry | Q2: Hrs | S2: Date | T2: 3400 Steeles | U2: Hrs | W2: Date | X2: Richmond Hill | Y2: Hrs | AA2: Date | AB2: Ramada Cornwall | AC2: Hrs | AE2: Date | AF2: Manitou | AG2: Hrs
A3: 46033 | C3: 46038 | D3: Niloufar Shirvani BT | E3: 7 | G3: 46035 | H3: Leslie Bacares | I3: 6.5 | T3: NONE | W3: 46033 | X3: Andrew Verches | Y3: 13 | AA3: 46032 | AB3: Dheeraj Kumar | AC3: 8.5
A4: 46034 | G4: 46037 | H4: Leslie Bacares | I4: 7.5 | W4: 46034 | X4: Andrew Verches | Y4: 7 | AA4: 46035 | AB4: Dheeraj Kumar | AC4: 8.5
A5: 46035 | G5: 46037 | H5: Theresa Blackman | I5: 6.5 | W5: 46035 | X5: Andrew Verches | Y5: 7 | AA5: 46038 | AB5: Dheeraj Kumar | AC5: 8.5
A6: 46036 | H6: above are PAID | W6: 46036 | X6: Andrew Verches | Y6: 7 | AA6: 46039 | AB6: Dheeraj Kumar | AC6: 8.5
A7: 46037 | W7: 46037 | X7: Andrew Verches | Y7: 7
A8: 46038 | W8: 46039 | X8: Andrew Verches | Y8: 13
A9: 46039 | W9: 46041 | X9: Andrew Verches | Y9: 7
A10: 46040 | W10: 46042 | X10: Andrew Verches | Y10: 7
A11: 46041 | W11: 46044 | X11: Andrew Verches | Y11: 7
A12: 46042 | W12: 46045 | X12: Andrew Verches | Y12: 7
A13: 46043 | W13: 46032 | X13: Paxson Intal Figueroa | Y13: 7
A14: 46044 | W14: 46033 | X14: Paxson Intal Figueroa | Y14: 8
A15: 46045 | W15: 46035 | X15: Paxson Intal Figueroa | Y15: 7.5
W16: 46036 | X16: Paxson Intal Figueroa | Y16: 7.5
W17: 46037 | X17: Paxson Intal Figueroa | Y17: 7.5
W18: 46038 | X18: Paxson Intal Figueroa | Y18: 7
W19: 46039 | X19: Paxson Intal Figueroa | Y19: 6
W20: 46040 | X20: Paxson Intal Figueroa | Y20: 6
W21: 46043 | X21: Paxson Intal Figueroa | Y21: 7
W22: 46044 | X22: Paxson Intal Figueroa | Y22: 8
W23: 46045 | X23: Paxson Intal Figueroa | Y23: 7

Sheet MMJ
B1: PAY PERIOD January 10 - 23, 2025 | C1: HOURS | D1: TYPE | E1: RATE | F1: GROSS | G1: NET
L2: Carry Over (June 15-28) | M2: Carry Over (June 29 - July 12) | N2: Carry Over (July 13 - 26) | O2: Carry Over (July 27 - Aug 9) | P2: Carry Over (July 27 - Aug 9) | Q2: Carry Over (Aug 10 - 23) SKYWARD | R2: Carry Over (Aug 10 - 23) SKYWARD
B3: Skyward Building | J3: Hours
A4: 5 | B4: Marjorie Kae Sarenas | C4: 60 | D4: PAYROLL | E4: 17.6 | F4: =C4*E4 -> 1056 | G4: 938.48 | H4: =#REF!+#REF! -> #REF! | J4: =(H4+I4)/16.65 -> #REF! | K4: =SUM(N4:X4) -> 104.59847 | L4: 20.29 | M4: 20.585586 | N4: =20.5855855855856-0.12 -> 20.465586 | O4: 18.941441 | P4: 18.941441 | Q4: 23 | R4: 23.25
B6: CAE
B7: Pauline Patterson | C7: =GTA!C219 -> 32 | D7: PAYROLL | E7: 18 | F7: =C7*E7 -> 576 | G7: 589.28
E10: TOTAL | F10: =SUM(F2:F9) -> 1632 | G10: =SUM(G2:G9) -> 1527.76

Sheet SUBCON
A1: =MMJ!B1 -> PAY PERIOD January 10 - 23, 2025 | B1: HOURS | C1: TYPE | D1: RATE | E1: TOTAL
A2: Best Western Plus Scarborough (38 Estate Dr)
A3: Penina Nyanchoka Mang'era | B3: =GTA!F201 -> 0 | C3: SUBCON | D3: 16.65 | E3: =B3*D3 -> 0
I4: BEST WESTERN PLUS (38 ESTATE DR, SCARBOROUGH)
A5: Best Western Plus Scarborough (38 Estate Dr) TOTAL: | B5: =SUM(B2:B4) -> 0 | I5: BEST WESTERN PLUS OTTAWA (1876 ROBERTSON RD)
A7: Maple Hotels
A8: Sunshine Padilla Rebadulla (Printed on Monthly) | B8: =OTTAWA!C72 -> 0 | C8: SUBCON | D8: 18 | E8: =B8*D8 -> 0
I9: BEST WESTERN PLUS (38 ESTATE DR, SCARBOROUGH)
A10: Maple Hotels TOTAL: | B10: =SUM(B7:B9) -> 0 | I10: BEST WESTERN PLUS OTTAWA (1876 ROBERTSON RD)
A12: Sheraton Four Points Cambridge (210 Preston Pkwy)
A13: Marjorie Kae Sarenas | B13: 60 | C13: PAYROLL | D13: 17.6 | E13: 1032.83 | F13: Skyward Building
A14: Pauline Patterson | B14: 28 | C14: PAYROLL | D14: 18 | E14: 575.63 | F14: CAE
A15: Meet Vanraj Mahida | B15: ='OUTSIDE GTA'!G197 -> 0 | C15: SUBCON | D15: 16.65 | E15: =B15*D15 -> 0
A16: Satnam Singh | B16: ='OUTSIDE GTA'!E197 -> 0 | C16: SUBCON | D16: 16.65 | E16: =B16*D16 -> 0
A17: Sukhjot Singh | B17: ='OUTSIDE GTA'!D197 -> 0 | C17: SUBCON | D17: 16.65 | E17: =B17*D17 -> 0
A18: Rahul | B18: ='OUTSIDE GTA'!H197 -> 0 | C18: SUBCON | D18: 16.65 | E18: =B18*D18 -> 0
A19: Sukhjot Singh K | B19: ='OUTSIDE GTA'!F197 -> 0 | C19: SUBCON | D19: 16.65 | E19: =B19*D19 -> 0
A20: Gurbeer | B20: ='OUTSIDE GTA'!I197 -> 0 | C20: SUBCON | D20: 16.65 | E20: =B20*D20 -> 0
A22: Sheraton Four Points Cambridge (210 Preston Pkwy) | B22: =SUM(B12:B21) -> 88
A24: Manitou Springs Resort and Mineral Spa (302 MacLachlan Ave)
A25: Huberto | B25: ='OUTSIDE GTA'!C17 -> 0 | C25: SUBCON | D25: 16.5 | E25: =B25*D25 -> 0
A26: Willy (Less $64.52 Accommodation for 4 days) | B26: ='OUTSIDE GTA'!D17 -> 0 | C26: SUBCON | D26: 16.5 | E26: =(B26*D26)-64.52 -> -64.52 | F26: Manitou Springs Resort and Mineral Spa (302 MacLachlan Ave) | G26: =(500/31)*4 -> 64.516129
C27: SUBCON | E27: =B27*D27 -> 0 | I27: DELTA TORONTO EAST (2035 SCARBOROUGH)
C28: SUBCON | E28: =B28*D28 -> 0
I29: BEST WESTERN PLUS (38 ESTATE DR, SCARBOROUGH)
A30: Holiday Inn Express Woodstock (510 Norwich Ave) TOTAL: | B30: =SUM(B24:B29) -> 0 | I30: BEST WESTERN PLUS OTTAWA (1876 ROBERTSON RD)
A32: Merland Park Cottages (12488 Loyalist Pkwy)
A33: Richard Canillas | B33: ='OUTSIDE GTA'!C270 -> 0 | C33: SUBCON | D33: 18 | E33: =B33*D33 -> 0
A34: Jeffrey | B34: ='OUTSIDE GTA'!D270 -> 0 | C34: SUBCON | D34: 18 | E34: =B34*D34 -> 0 | I34: DELTA TORONTO EAST (2035 SCARBOROUGH)
A35: Rita Shalimar C. Aradillos | B35: ='OUTSIDE GTA'!E270 -> 0 | C35: SUBCON | D35: 18 | E35: =B35*D35 -> 0
A36: Gurpreet | B36: ='OUTSIDE GTA'!F270 -> 0 | C36: SUBCON | D36: 18 | E36: =B36*D36 -> 0
A37: Dikaran | B37: ='OUTSIDE GTA'!G270 -> 0 | C37: SUBCON | D37: 18 | E37: =B37*D37 -> 0
I38: BEST WESTERN PLUS (38 ESTATE DR, SCARBOROUGH)
A39: Merland Park Cottages (12488 Loyalist Pkwy) TOTAL: | B39: =SUM(B32:B38) -> 0 | I39: BEST WESTERN PLUS OTTAWA (1876 ROBERTSON RD)
A41: Tru by Hilton Bracebridge (320 Taylor Rd, Bracebridge)
A42: Armando | B42: ='OUTSIDE GTA'!C288 -> 0 | C42: SUBCON | D42: 16.65 | E42: =B42*D42 -> 0
A43: Shirley | B43: ='OUTSIDE GTA'!D288 -> 0 | C43: SUBCON | D43: 16.65 | E43: =B43*D43 -> 0 | I43: DELTA TORONTO EAST (2035 SCARBOROUGH)
I44: BEST WESTERN PLUS (38 ESTATE DR, SCARBOROUGH)
A45: Tru by Hilton Bracebridge (320 Taylor Rd, Bracebridge) | B45: =SUM(B41:B44) -> 0 | I45: BEST WESTERN PLUS OTTAWA (1876 ROBERTSON RD)
A47: Home 2 by Hilton Woodstock (527 Lampman Pl)
...

Sheet SUBCON (2)
A1: PAY PERIOD September 20 - October 3, 2025 | B1: HOURS | C1: TYPE | D1: RATE | E1: TOTAL | F1: HOTEL
A2: Best Western Plus Scarborough (38 Estate Dr)
A3: Penina Nyanchoka Mang'era | B3: =GTA!F201 -> 0 | C3: SUBCON | D3: 16.65 | E3: =B3*D3 -> 0
A5: Best Western Plus Scarborough (38 Estate Dr) TOTAL: | B5: =SUM(B2:B4) -> 0
A7: Maple Hotels
A8: Sunshine Padilla Rebadulla (Printed on Monthly) | B8: =OTTAWA!C72 -> 0 | C8: SUBCON | D8: 18 | E8: =B8*D8 -> 0
A10: Maple Hotels TOTAL: | B10: =SUM(B7:B9) -> 0
A12: Sheraton Four Points Cambridge (210 Preston Pkwy)
A13: Joshua Agorilla | B13: ='OUTSIDE GTA'!C197 -> 0 | C13: SUBCON | D13: 16.65 | E13: =B13*D13 -> 0
A14: Aakash | B14: ='OUTSIDE GTA'!J197 -> 0 | C14: SUBCON | D14: 16.65 | E14: =B14*D14 -> 0
A15: Meet Vanraj Mahida | B15: ='OUTSIDE GTA'!G197 -> 0 | C15: SUBCON | D15: 16.65 | E15: =B15*D15 -> 0
A16: Satnam Singh | B16: ='OUTSIDE GTA'!E197 -> 0 | C16: SUBCON | D16: 16.65 | E16: =B16*D16 -> 0
A17: Sukhjot Singh | B17: ='OUTSIDE GTA'!D197 -> 0 | C17: SUBCON | D17: 16.65 | E17: =B17*D17 -> 0
A18: Rahul | B18: ='OUTSIDE GTA'!H197 -> 0 | C18: SUBCON | D18: 16.65 | E18: =B18*D18 -> 0
A19: Sukhjot Singh K | B19: ='OUTSIDE GTA'!F197 -> 0 | C19: SUBCON | D19: 16.65 | E19: =B19*D19 -> 0
A20: Gurbeer | B20: ='OUTSIDE GTA'!I197 -> 0 | C20: SUBCON | D20: 16.65 | E20: =B20*D20 -> 0
A22: Sheraton Four Points Cambridge (210 Preston Pkwy) | B22: =SUM(B12:B21) -> 0
A24: Holiday Inn Express Woodstock (510 Norwich Ave)
A25: Michelle Enriquez | B25: ='OUTSIDE GTA'!D17 -> 0 | C25: SUBCON | D25: 17 | E25: =B25*D25 -> 0 | F25: Holiday Inn Express Woodstock (510 Norwich Ave)
A26: Angel Ellan | B26: ='OUTSIDE GTA'!Q17 -> 0 | C26: SUBCON | D26: 17 | E26: =B26*D26 -> 0 | F26: Holiday Inn Express Woodstock (510 Norwich Ave)
A27: Menandro | B27: ='OUTSIDE GTA'!P17 -> 0 | C27: SUBCON | D27: 16.65 | E27: =B27*D27 -> 0 | F27: Holiday Inn Express Woodstock (510 Norwich Ave)
A28: Herbert | B28: ='OUTSIDE GTA'!C17 -> 0 | C28: SUBCON | D28: 16.65 | E28: =B28*D28 -> 0 | F28: Holiday Inn Express Woodstock (510 Norwich Ave)
A30: Holiday Inn Express Woodstock (510 Norwich Ave) TOTAL: | B30: =SUM(B24:B29) -> 0
A32: Merland Park Cottages (12488 Loyalist Pkwy)
A33: Richard Canillas | B33: ='OUTSIDE GTA'!C270 -> 0 | C33: SUBCON | D33: 18 | E33: =B33*D33 -> 0
A34: Jeffrey | B34: ='OUTSIDE GTA'!D270 -> 0 | C34: SUBCON | D34: 18 | E34: =B34*D34 -> 0
A35: Rita Shalimar C. Aradillos | B35: ='OUTSIDE GTA'!E270 -> 0 | C35: SUBCON | D35: 18 | E35: =B35*D35 -> 0
A36: Gurpreet | B36: ='OUTSIDE GTA'!F270 -> 0 | C36: SUBCON | D36: 18 | E36: =B36*D36 -> 0
A37: Dikaran | B37: ='OUTSIDE GTA'!G270 -> 0 | C37: SUBCON | D37: 18 | E37: =B37*D37 -> 0
A39: Merland Park Cottages (12488 Loyalist Pkwy) TOTAL: | B39: =SUM(B32:B38) -> 0
A41: Tru by Hilton Bracebridge (320 Taylor Rd, Bracebridge)
A42: Armando | B42: ='OUTSIDE GTA'!C288 -> 0 | C42: SUBCON | D42: 16.65 | E42: =B42*D42 -> 0
A43: Shirley | B43: ='OUTSIDE GTA'!D288 -> 0 | C43: SUBCON | D43: 16.65 | E43: =B43*D43 -> 0
A45: Tru by Hilton Bracebridge (320 Taylor Rd, Bracebridge) | B45: =SUM(B41:B44) -> 0
A47: Home 2 by Hilton Woodstock (527 Lampman Pl)
A48: Menandro | B48: ='OUTSIDE GTA'!C35 -> 0 | C48: SUBCON | D48: 16.65 | E48: =B48*D48 -> 0 | F48: Home 2 by Hilton Woodstock (527 Lampman Pl)
A49: Catherine Martin | B49: ='OUTSIDE GTA'!G35 -> 0 | C49: SUBCON | D49: 16.65 | E49: =B49*D49 -> 0 | F49: Home 2 by Hilton Woodstock (527 Lampman Pl)
A50: Jonervin Agustin | B50: ='OUTSIDE GTA'!D35 -> 0 | C50: SUBCON | D50: 16.65 | E50: =B50*D50 -> 0 | F50: Home 2 by Hilton Woodstock (527 Lampman Pl)
A51: Dhruvkumar Harshadkumar Patel | B51: ='OUTSIDE GTA'!E35 -> 0 | C51: SUBCON | D51: 16.65 | E51: =B51*D51 -> 0 | F51: Home 2 by Hilton Woodstock (527 Lampman Pl)
A52: Sukhjivan Singh | B52: ='OUTSIDE GTA'!F35 -> 0 | C52: SUBCON | D52: 16.65 | E52: =B52*D52 -> 0 | F52: Home 2 by Hilton Woodstock (527 Lampman Pl)
...

Sheet Tally
A1: Hotel | B1: Subcon / Payroll | C1: Timesheet
A2: BC.Holiday Inn Elk Lake Victoria BC (4670 Elk Lake Drive) | B2: ='British Columbia'!T19 -> 111.5 | C2: ='British Columbia'!T19 -> 111.5 | D2: =IF(B2=C2, "✔", "❌❌❌") -> ✔ | F2: =B2-C2 -> 0
A3: BC.Holiday Inn Express & Suites Victoria - Colwood (318 Wale Rd) | B3: ='SUBCON - BC'!B32 -> 0 | C3: =SUM('British Columbia'!C29:S35) -> 0 | D3: =IF(B3=C3, "✔", "❌❌❌") -> ✔ | F3: =B3-C3 -> 0
A4: BC.Motel 6 Saanichton Victoria Airport BC (2401 Mt Newton Cross Rd) | B4: ='SUBCON - BC'!B53 -> 0 | C4: =SUM('British Columbia'!C48:S54) -> 0 | D4: =IF(B4=C4, "✔", "❌❌❌") -> ✔ | F4: =B4-C4 -> 0
A5: Best Western Plus Muskoka Inn (86 Howland Dr) | B5: =SUBCON!B96 -> 0 | C5: ='OUTSIDE GTA'!B143 -> 0 | D5: =IF(B5=C5, "✔", "❌❌❌") -> ✔ | F5: =B5-C5 -> 0
A6: Best Western Plus Ottawa (1876 Robertson Rd) | B6: =SUBCON!B201 -> 0 | C6: =OTTAWA!B18 -> 0 | D6: =IF(B6=C6, "✔", "❌❌❌") -> ✔ | F6: =B6-C6 -> 0
A7: Best Western Plus Scarborough (38 Estate Dr) | B7: =SUBCON!B5 -> 0 | C7: =GTA!B201 -> 0 | D7: =IF(B7=C7, "✔", "❌❌❌") -> ✔ | F7: =B7-C7 -> 0
A8: CAE (2025 Logistics Dr) | B8: =MMJ!C7 -> 32 | C8: =GTA!B219 -> 32 | D8: =IF(B8=C8, "✔", "❌❌❌") -> ✔ | F8: =B8-C8 -> 0
A9: Chatham-Kent | B9: =SUBCON!B838 -> 0 | C9: ='OUTSIDE GTA'!B107 -> 0 | D9: =IF(B9=C9, "✔", "❌❌❌") -> ✔ | F9: =B9-C9 -> 0
A10: Courtyard and TownePlace Suites Oshawa (1011 Bloor St E) | B10: =SUBCON!B253 -> 0 | C10: =GTA!B147 -> 0 | D10: =IF(B10=C10, "✔", "❌❌❌") -> ✔ | F10: =B10-C10 -> 0
A11: Courtyard by Marriott Toronto Mississauga West (290 Derry Rd W) | B11: =SUBCON!B237 -> 0 | C11: =GTA!B129 -> 0 | D11: =IF(B11=C11, "✔", "❌❌❌") -> ✔ | F11: =B11-C11 -> 0
A12: Days Inn Ottawa Downtown (319 Rideau St) | B12: =SUBCON!B135 -> 0 | C12: =OTTAWA!B54 -> 0
A13: Days Inn Ottawa West (350 Moodie Dr) | B13: =SUBCON!B348 -> 0 | C13: =OTTAWA!B36 -> 0 | D13: =IF(B13=C13, "✔", "❌❌❌") -> ✔ | F13: =B13-C13 -> 0
A14: Delta Toronto East Scarborough (2035 Kennedy Rd) | B14: =SUBCON!B363 -> 0 | C14: =GTA!B363 -> 0 | D14: =IF(B14=C14, "✔", "❌❌❌") -> ✔ | F14: =B14-C14 -> 0
A15: Edward Hotel North York (185 Yorkland Blvd) | B15: =SUBCON!B398 -> 0 | C15: =GTA!B111 -> 0 | D15: =IF(B15=C15, "✔", "❌❌❌") -> ✔ | F15: =B15-C15 -> 0
A16: Fairfield Inn and Suites Brampton (150 Westcreek Blvd) | B16: =SUBCON!B403 -> 0 | C16: =GTA!B381 -> 0 | D16: =IF(B16=C16, "✔", "❌❌❌") -> ✔ | F16: =B16-C16 -> 0
A17: Gupta Household Stratford (53 McFarlane Street) | B17: =SUBCON!B557 -> 0 | C17: ='OUTSIDE GTA'!B215 -> 0
A18: Hampton Inn Midland (877 King St) | B18: =SUBCON!B884 -> 0 | C18: ='OUTSIDE GTA'!B161 -> 0 | D18: =IF(B18=C18, "✔", "❌❌❌") -> ✔
A19: Hidden Valley Resort Muskoka (1755 Valley Rd) | B19: =SUBCON!B90 -> 0 | C19: ='OUTSIDE GTA'!B71 -> 0 | D19: =IF(B19=C19, "✔", "❌❌❌") -> ✔ | F19: =B19-C19 -> 0
A20: Hilton Toronto Markham (8500 Warden Ave) | B20: =SUBCON!B476 -> 0 | C20: =GTA!B255 -> 0 | D20: =IF(B20=C20, "✔", "❌❌❌") -> ✔ | F20: =B20-C20 -> 0
A21: Holiday Inn Burlington (3063 S Service Rd) | B21: =SUBCON!B543 -> 20.5 | C21: =GTA!B273 -> 20.5 | D21: =IF(B21=C21, "✔", "❌❌❌") -> ✔ | F21: =B21-C21 -> 0
A22: Holiday Inn Express Mississauga (2125 N Sheridan W) | B22: =SUBCON!B639 -> 0 | C22: =GTA!B57 -> 0 | D22: =IF(B22=C22, "✔", "❌❌❌") -> ✔ | F22: =B22-C22 -> 0
A23: Holiday Inn Express North York (30 Norfinch Dr) | B23: =SUBCON!B373 -> 0 | C23: =GTA!B93 -> 0 | D23: =IF(B23=C23, "✔", "❌❌❌") -> ✔ | F23: =B23-C23 -> 0
A24: Holiday Inn Express Richmond Hill (10 East Pearce St) | B24: =SUBCON!B577 -> 160.5 | C24: =GTA!B39 -> 160.5 | D24: =IF(B24=C24, "✔", "❌❌❌") -> ✔ | F24: =B24-C24 -> 0
A25: Holiday Inn Express Toronto East (50 Estate Dr) | B25: =SUBCON!B647 -> 0 | C25: =GTA!B399 -> 0 | D25: =IF(B25=C25, "✔", "❌❌❌") -> ✔ | F25: =B25-C25 -> 0
A26: Holiday Inn Express Woodstock (510 Norwich Ave) | B26: =SUBCON!B30 -> 0 | C26: ='OUTSIDE GTA'!B17 -> 0 | D26: =IF(B26=C26, "✔", "❌❌❌") -> ✔ | F26: =B26-C26 -> 0
A27: Home 2 by Hilton Woodstock (527 Lampman Pl) | B27: =SUBCON!B58 -> 0 | C27: ='OUTSIDE GTA'!B35 -> 0 | D27: =IF(B27=C27, "✔", "❌❌❌") -> ✔ | F27: =B27-C27 -> 0
A28: Hyatt Place Mississauga (5787 Hurontario St) | B28: =SUBCON!B803 -> 7 | C28: =GTA!B21 -> 7 | D28: =IF(B28=C28, "✔", "❌❌❌") -> ✔ | F28: =B28-C28 -> 0
A29: Knights Inn Toronto East (22 Metropolitan) | B29: =SUBCON!B815 -> 0 | C29: =GTA!B475 -> 0 | D29: =IF(B29=C29, "✔", "❌❌❌") -> ✔ | F29: =B29-C29 -> 0
A30: McKesson Canada - Airport (665B Airport Rd) | D30: =IF(B30=C30, "✔", "❌❌❌") -> ✔ | F30: =B30-C30 -> 0
A31: Merland Park Cottages (12488 Loyalist Pkwy) | B31: =SUBCON!B39 -> 0 | C31: ='OUTSIDE GTA'!B270 -> 0 | D31: =IF(B31=C31, "✔", "❌❌❌") -> ✔ | F31: =B31-C31 -> 0
A32: Quality Inn & Suites Regina Downtown (1907 11th Ave) | B32: =SUBCON!B67 -> 0 | C32: ='OUTSIDE GTA'!B125 -> 0 | D32: =IF(B32=C32, "✔", "❌❌❌") -> ✔ | F32: =B32-C32 -> 0
A33: Radisson Toronto East (55 Hallcrown Pl) | B33: =SUBCON!B849 -> 0 | C33: =GTA!B75 -> 0 | D33: =IF(B33=C33, "✔", "❌❌❌") -> ✔ | F33: =B33-C33 -> 0
A34: Ramada by Wyndham Cornwall (805 Brookdale Ave) | B34: =SUBCON!B855 -> 34 | C34: ='OUTSIDE GTA'!B179 -> 34 | D34: =IF(B34=C34, "✔", "❌❌❌") -> ✔ | F34: =B34-C34 -> 0
A35: Ramada by Wyndham Niagara Falls by the River (4357 River Rd) | B35: =SUBCON!B909 -> 0 | C35: ='OUTSIDE GTA'!B89 -> 0 | D35: =IF(B35=C35, "✔", "❌❌❌") -> ✔ | F35: =B35-C35 -> 0
A36: Sheraton Four Points Cambridge (210 Preston Pky) | B36: =SUBCON!B22 -> 88 | C36: ='OUTSIDE GTA'!B197 -> 0 | D36: =IF(B36=C36, "✔", "❌❌❌") -> ❌❌❌ | F36: =B36-C36 -> 88
A37: Sheraton Four Points Hamilton (49 Goderich Rd) | B37: =SUBCON!B432 -> 0 | C37: ='OUTSIDE GTA'!B233 -> 0 | D37: =IF(B37=C37, "✔", "❌❌❌") -> ✔ | F37: =B37-C37 -> 0
A38: Sheraton Four Points Toronto Airport East (2180 Islington Ave ) | B38: =SUBCON!B408 -> 0 | C38: =GTA!B237 -> 0 | D38: =IF(B38=C38, "✔", "❌❌❌") -> ✔ | F38: =B38-C38 -> 0
A39: Sheraton Four Points Vaughan (3400 Steeles Ave W) | B39: =SUBCON!B591 -> 0 | C39: =SUM(GTA!D165:R165) -> 0 | D39: =IF(B39=C39, "✔", "❌❌❌") -> ✔ | F39: =B39-C39 -> 0
A40: Spark by Hilton Woodstock (560 Norwich Ave) | B40: =SUBCON!B127 -> 0 | C40: ='OUTSIDE GTA'!B53 -> 0 | D40: =IF(B40=C40, "✔", "❌❌❌") -> ✔ | F40: =B40-C40 -> 0
...

Sheet Master List
A1: =MMJ!B1 -> PAY PERIOD January 10 - 23, 2025 | B1: HOURS | C1: TYPE | D1: RATE | E1: TOTAL | F1: Hotel
A2: Andrew Verches | B2: 82 | C2: SUBCON | D2: 16.65 | E2: 1365.3 | F2: Holiday Inn Express Richmond Hill (10 East Pearce St)
A3: Dheeraj Kumar I | B3: 34 | C3: SUBCON | D3: 18 | E3: 612 | F3: Ramada by Wyndham Cornwall (805 Brookdale Ave)
A4: Leslie Bacares - PAID | B4: 14 | C4: SUBCON | D4: 16.65 | E4: 233.1 | F4: Holiday Inn Burlington (3063 S Service Rd)
A5: Niloufar Shirvani | B5: 7 | C5: SUBCON | D5: 20 | E5: 140 | F5: Hyatt Place Mississauga (5787 Hurontario St)
A6: Pauline Patterson | B6: 32 | C6: PAYROLL | D6: 18 | E6: 589.28 | F6: CAE
A7: Paxson Intal Figueroa | B7: 78.5 | C7: SUBCON | D7: 16.65 | E7: 1307.025 | F7: Holiday Inn Express Richmond Hill (10 East Pearce St)
A8: Theresa Blackman - PAID | B8: 6.5 | C8: SUBCON | D8: 16.65 | E8: 108.225 | F8: Holiday Inn Burlington (3063 S Service Rd)
H66: ='SUMMARY A-Z'!F8 -> 1093.325 | I66: {='Summary Hotel'!D191:E191} -> 3261.605 | J66: 0
D67: TOTAL: | E67: =SUM(E1:E66) -> 4354.93
E68: =SUM(H66:I66) -> 4354.93 | F68: =E67-E68 -> 0

Sheet SUMMARY A-Z
A1: =MMJ!B1 -> PAY PERIOD January 10 - 23, 2025 | B1: Mail or Pickup | C1: HOURS | D1: TYPE | E1: RATE | F1: TOTAL | G1: Hotel | H1: Interac
A2: Dheeraj Kumar | B2: =VLOOKUP(A2,Table4[[Name]:[Mail or Pickup]],7,FALSE) -> ** | C2: 34 | D2: SUBCON | E2: 18 | F2: 612 | G2: Ramada by Wyndham Cornwall (805 Brookdale Ave) | H2: =VLOOKUP(A2,Subcontractors!B2:D1734,3,FALSE) -> dheerajkashyap615@gmail.com
A3: Leslie Bacares - PAID | C3: 14 | D3: SUBCON | E3: 16.65 | F3: 233.1 | G3: Holiday Inn Burlington (3063 S Service Rd) | H3: Bacaresleslie@gmail.com
A4: Niloufar Shirvani | B4: =VLOOKUP(A4,Table4[[Name]:[Mail or Pickup]],7,FALSE) -> ** | C4: 7 | D4: SUBCON | E4: 20 | F4: 140 | G4: Hyatt Place Mississauga (5787 Hurontario St) | H4: =VLOOKUP(A4,Subcontractors!B4:D1736,3,FALSE) -> shirvaninli@gmail.com
A5: Theresa Blackman -PAID | C5: 6.5 | D5: SUBCON | E5: 16.65 | F5: 108.225 | G5: Holiday Inn Burlington (3063 S Service Rd) | H5: theresablackman75@yahoo.com
H6: =_xlfn.IFNA(VLOOKUP(A6, Table4[[Name]:[Interac Email Final]], 3, FALSE), "")
A7: Total | E7: =SUM(F2:F6) -> 1093.325
F8: =E7 -> 1093.325

Sheet SUBCON (4)
A1: PAY PERIOD September 20 - October 3, 2025 | B1: HOURS | C1: TYPE | D1: RATE | E1: TOTAL | F1: HOTEL
A2: Best Western Plus Scarborough (38 Estate Dr)
A3: Penina Nyanchoka Mang'era | B3: =GTA!F201 -> 0 | C3: SUBCON | D3: 16.65 | E3: =B3*D3 -> 0
A5: Best Western Plus Scarborough (38 Estate Dr) TOTAL: | B5: =SUM(B2:B4) -> 0
A7: Maple Hotels
A8: Sunshine Padilla Rebadulla (Printed on Monthly) | B8: =OTTAWA!C72 -> 0 | C8: SUBCON | D8: 18 | E8: =B8*D8 -> 0
A10: Maple Hotels TOTAL: | B10: =SUM(B7:B9) -> 0
A12: Sheraton Four Points Cambridge (210 Preston Pkwy)
A13: Joshua Agorilla | B13: ='OUTSIDE GTA'!C197 -> 0 | C13: SUBCON | D13: 16.65 | E13: =B13*D13 -> 0
A14: Aakash | B14: ='OUTSIDE GTA'!J197 -> 0 | C14: SUBCON | D14: 16.65 | E14: =B14*D14 -> 0
A15: Meet Vanraj Mahida | B15: ='OUTSIDE GTA'!G197 -> 0 | C15: SUBCON | D15: 16.65 | E15: =B15*D15 -> 0
A16: Satnam Singh | B16: ='OUTSIDE GTA'!E197 -> 0 | C16: SUBCON | D16: 16.65 | E16: =B16*D16 -> 0
A17: Sukhjot Singh | B17: ='OUTSIDE GTA'!D197 -> 0 | C17: SUBCON | D17: 16.65 | E17: =B17*D17 -> 0
A18: Rahul | B18: ='OUTSIDE GTA'!H197 -> 0 | C18: SUBCON | D18: 16.65 | E18: =B18*D18 -> 0
A19: Sukhjot Singh K | B19: ='OUTSIDE GTA'!F197 -> 0 | C19: SUBCON | D19: 16.65 | E19: =B19*D19 -> 0
A20: Gurbeer | B20: ='OUTSIDE GTA'!I197 -> 0 | C20: SUBCON | D20: 16.65 | E20: =B20*D20 -> 0
A22: Sheraton Four Points Cambridge (210 Preston Pkwy) | B22: =SUM(B12:B21) -> 0
A24: Holiday Inn Express Woodstock (510 Norwich Ave)
A25: Angel Ellan | B25: ='OUTSIDE GTA'!Q17 -> 0 | C25: SUBCON | D25: 17 | E25: =B25*D25 -> 0 | F25: Holiday Inn Express Woodstock (510 Norwich Ave)
A26: Menandro | B26: ='OUTSIDE GTA'!P17 -> 0 | C26: SUBCON | D26: 16.65 | E26: =B26*D26 -> 0 | F26: Holiday Inn Express Woodstock (510 Norwich Ave)
A28: Holiday Inn Express Woodstock (510 Norwich Ave) TOTAL: | B28: =SUM(B24:B27) -> 0
A30: Merland Park Cottages (12488 Loyalist Pkwy)
A31: Richard Canillas | B31: ='OUTSIDE GTA'!C270 -> 0 | C31: SUBCON | D31: 18 | E31: =B31*D31 -> 0
A32: Jeffrey | B32: ='OUTSIDE GTA'!D270 -> 0 | C32: SUBCON | D32: 18 | E32: =B32*D32 -> 0
A33: Rita Shalimar C. Aradillos | B33: ='OUTSIDE GTA'!E270 -> 0 | C33: SUBCON | D33: 18 | E33: =B33*D33 -> 0
A34: Gurpreet | B34: ='OUTSIDE GTA'!F270 -> 0 | C34: SUBCON | D34: 18 | E34: =B34*D34 -> 0
A35: Dikaran | B35: ='OUTSIDE GTA'!G270 -> 0 | C35: SUBCON | D35: 18 | E35: =B35*D35 -> 0
A37: Merland Park Cottages (12488 Loyalist Pkwy) TOTAL: | B37: =SUM(B30:B36) -> 0
A39: Tru by Hilton Bracebridge (320 Taylor Rd, Bracebridge)
A40: Armando | B40: ='OUTSIDE GTA'!C288 -> 0 | C40: SUBCON | D40: 16.65 | E40: =B40*D40 -> 0
A41: Shirley | B41: ='OUTSIDE GTA'!D288 -> 0 | C41: SUBCON | D41: 16.65 | E41: =B41*D41 -> 0
A43: Tru by Hilton Bracebridge (320 Taylor Rd, Bracebridge) | B43: =SUM(B39:B42) -> 0
A45: Home 2 by Hilton Woodstock (527 Lampman Pl)
A46: Menandro | B46: ='OUTSIDE GTA'!C35 -> 0 | C46: SUBCON | D46: 16.65 | E46: =B46*D46 -> 0 | F46: Home 2 by Hilton Woodstock (527 Lampman Pl)
A47: Jonervin Agustin | B47: ='OUTSIDE GTA'!D35 -> 0 | C47: SUBCON | D47: 16.65 | E47: =B47*D47 -> 0 | F47: Home 2 by Hilton Woodstock (527 Lampman Pl)
A48: Dhruvkumar Harshadkumar Patel | B48: ='OUTSIDE GTA'!E35 -> 0 | C48: SUBCON | D48: 16.65 | E48: =B48*D48 -> 0 | F48: Home 2 by Hilton Woodstock (527 Lampman Pl)
A49: Sukhjivan Singh | B49: ='OUTSIDE GTA'!F35 -> 0 | C49: SUBCON | D49: 16.65 | E49: =B49*D49 -> 0 | F49: Home 2 by Hilton Woodstock (527 Lampman Pl)
A50: Harkirat Singh | B50: ='OUTSIDE GTA'!H35 -> 0 | C50: SUBCON | D50: 16.65 | E50: =B50*D50 -> 0 | F50: Home 2 by Hilton Woodstock (527 Lampman Pl)
A51: Gagandeep Singh | B51: ='OUTSIDE GTA'!I35 -> 0 | C51: SUBCON | D51: 16.65 | E51: =B51*D51 -> 0 | F51: Home 2 by Hilton Woodstock (527 Lampman Pl)
A52: Casey Alexis Rapisura | B52: ='OUTSIDE GTA'!J35 -> 0 | C52: SUBCON | D52: 16.65 | E52: =B52*D52 -> 0 | F52: Home 2 by Hilton Woodstock (527 Lampman Pl)
...

Sheet Summary Hotel
A1: Hotel
A2: BEST WESTERN PLUS OTTAWA (1876 ROBERTSON RD)
A3: =MMJ!B1 -> PAY PERIOD January 10 - 23, 2025 | B3: HOURS | C3: TYPE | D3: RATE | E3: TOTAL | F3: Hotel | G3: Etransfer
G4: =VLOOKUP(A4,'[1]Interac Details'!$A:$B, 2, FALSE) -> 0
G5: =VLOOKUP(A5,'[1]Interac Details'!$A:$B, 2, FALSE) -> 0
G6: =VLOOKUP(A6,'[1]Interac Details'!$A:$B, 2, FALSE) -> 0
G7: =VLOOKUP(A7,'[1]Interac Details'!$A:$B, 2, FALSE) -> 0
G8: =VLOOKUP(A8,'[1]Interac Details'!$A:$B, 2, FALSE) -> 0
G9: =VLOOKUP(A9,'[1]Interac Details'!$A:$B, 2, FALSE) -> 0
G10: =VLOOKUP(A10,'[1]Interac Details'!$A:$B, 2, FALSE) -> 0
G11: =VLOOKUP(A11,'[1]Interac Details'!$A:$B, 2, FALSE) -> 0
G12: =VLOOKUP(A12,'[1]Interac Details'!$A:$B, 2, FALSE) -> 0
G13: =VLOOKUP(A13,'[1]Interac Details'!$A:$B, 2, FALSE) -> 0
G14: =VLOOKUP(A14,'[1]Interac Details'!$A:$B, 2, FALSE) -> 0
G15: =VLOOKUP(A15,'[1]Interac Details'!$A:$B, 2, FALSE) -> 0
... G17: =VLOOKUP(A17,'[1]Interac Details'!$A:$B, 2, FALSE) -> 0
B19: Total | D19: =SUM(E4:E17) -> 0 | H19: =D19 -> 0
A20: DAYS INN OTTAWA WEST (350 MOODIE DR, OTTAWA)
A21: =A3 -> PAY PERIOD January 10 - 23, 2025 | B21: HOURS | C21: TYPE | D21: RATE | E21: TOTAL | F21: Hotel | G21: Etransfer
G22: =VLOOKUP(A22,'[1]Interac Details'!$A:$B, 2, FALSE) -> 0
G23: =VLOOKUP(A23,'[1]Interac Details'!$A:$B, 2, FALSE) -> 0
G24: =VLOOKUP(A24,'[1]Interac Details'!$A:$B, 2, FALSE) -> 0
G25: =VLOOKUP(A25,'[1]Interac Details'!$A:$B, 2, FALSE) -> 0
G26: =VLOOKUP(A26,'[1]Interac Details'!$A:$B, 2, FALSE) -> 0
G27: =VLOOKUP(A27,'[1]Interac Details'!$A:$B, 2, FALSE) -> 0
G28: =VLOOKUP(A28,'[1]Interac Details'!$A:$B, 2, FALSE) -> 0
G29: =VLOOKUP(A29,'[1]Interac Details'!$A:$B, 2, FALSE) -> 0
G30: =VLOOKUP(A30,'[1]Interac Details'!$A:$B, 2, FALSE) -> 0
G31: =VLOOKUP(A31,'[1]Interac Details'!$A:$B, 2, FALSE) -> 0
G32: =VLOOKUP(A32,'[1]Interac Details'!$A:$B, 2, FALSE) -> 0
G33: =VLOOKUP(A33,'[1]Interac Details'!$A:$B, 2, FALSE) -> 0
G34: =VLOOKUP(A34,'[1]Interac Details'!$A:$B, 2, FALSE) -> 0
B36: Total | D36: =SUM(E22:E35) -> 0 | H36: =D36 -> 0
A37: EDWARD HOTEL (185 YORKLAND BLVD NORTH YORK)
A38: =A3 -> PAY PERIOD January 10 - 23, 2025 | B38: HOURS | C38: TYPE | D38: RATE | E38: TOTAL | F38: Hotel | G38: Etransfer
G39: =VLOOKUP(A39,'Interac Details'!A:B, 2, FALSE) -> 0
G40: =VLOOKUP(A40,'Interac Details'!A:B, 2, FALSE) -> 0
B43: Total | D43: =SUM(E39:E41) -> 0
A45: HOLIDAY INN EXPRESS - RICHMOND HILL
A46: =A3 -> PAY PERIOD January 10 - 23, 2025 | B46: HOURS | C46: TYPE | D46: RATE | E46: TOTAL | G46: Etransfer
...

Sheet SUBCON (3)
A1: PAY PERIOD September 20 - October 3, 2025 | B1: HOURS | C1: TYPE | D1: RATE | E1: TOTAL | F1: HOTEL
A2: Best Western Plus Scarborough (38 Estate Dr)
A3: Penina Nyanchoka Mang'era | B3: =GTA!F201 -> 0 | C3: SUBCON | D3: 16.65 | E3: =B3*D3 -> 0
A5: Best Western Plus Scarborough (38 Estate Dr) TOTAL: | B5: =SUM(B2:B4) -> 0
A7: Maple Hotels
A8: Sunshine Padilla Rebadulla (Printed on Monthly) | B8: =OTTAWA!C72 -> 0 | C8: SUBCON | D8: 18 | E8: =B8*D8 -> 0
A10: Maple Hotels TOTAL: | B10: =SUM(B7:B9) -> 0
A12: Sheraton Four Points Cambridge (210 Preston Pkwy)
A13: Joshua Agorilla | B13: ='OUTSIDE GTA'!C197 -> 0 | C13: SUBCON | D13: 16.65 | E13: =B13*D13 -> 0
A14: Aakash | B14: ='OUTSIDE GTA'!J197 -> 0 | C14: SUBCON | D14: 16.65 | E14: =B14*D14 -> 0
A15: Meet Vanraj Mahida | B15: ='OUTSIDE GTA'!G197 -> 0 | C15: SUBCON | D15: 16.65 | E15: =B15*D15 -> 0
A16: Satnam Singh | B16: ='OUTSIDE GTA'!E197 -> 0 | C16: SUBCON | D16: 16.65 | E16: =B16*D16 -> 0
A17: Sukhjot Singh | B17: ='OUTSIDE GTA'!D197 -> 0 | C17: SUBCON | D17: 16.65 | E17: =B17*D17 -> 0
A18: Rahul | B18: ='OUTSIDE GTA'!H197 -> 0 | C18: SUBCON | D18: 16.65 | E18: =B18*D18 -> 0
A19: Sukhjot Singh K | B19: ='OUTSIDE GTA'!F197 -> 0 | C19: SUBCON | D19: 16.65 | E19: =B19*D19 -> 0
A20: Gurbeer | B20: ='OUTSIDE GTA'!I197 -> 0 | C20: SUBCON | D20: 16.65 | E20: =B20*D20 -> 0
A22: Sheraton Four Points Cambridge (210 Preston Pkwy) | B22: =SUM(B12:B21) -> 0
A24: Holiday Inn Express Woodstock (510 Norwich Ave)
A25: Lyka | B25: ='OUTSIDE GTA'!C143 -> 0 | C25: SUBCON | D25: 20 | E25: =B25*D25 -> 0 | F25: BEST WESTERN PLUS MUSKOKA INN (86 HOWLAND DRIVE )
A26: Angel Ellan | B26: ='OUTSIDE GTA'!Q17 -> 0 | C26: SUBCON | D26: 17 | E26: =B26*D26 -> 0 | F26: Holiday Inn Express Woodstock (510 Norwich Ave)
A27: Menandro | B27: ='OUTSIDE GTA'!P17 -> 0 | C27: SUBCON | D27: 16.65 | E27: =B27*D27 -> 0 | F27: Holiday Inn Express Woodstock (510 Norwich Ave)
A28: Akin | B28: ='OUTSIDE GTA'!C107 -> 0 | C28: SUBCON | D28: 16.65 | E28: =B28*D28 -> 0 | F28: Chatham Kent
A30: Holiday Inn Express Woodstock (510 Norwich Ave) TOTAL: | B30: =SUM(B24:B29) -> 0
A32: Merland Park Cottages (12488 Loyalist Pkwy)
A33: Richard Canillas | B33: ='OUTSIDE GTA'!C270 -> 0 | C33: SUBCON | D33: 18 | E33: =B33*D33 -> 0
A34: Jeffrey | B34: ='OUTSIDE GTA'!D270 -> 0 | C34: SUBCON | D34: 18 | E34: =B34*D34 -> 0
A35: Rita Shalimar C. Aradillos | B35: ='OUTSIDE GTA'!E270 -> 0 | C35: SUBCON | D35: 18 | E35: =B35*D35 -> 0
A36: Gurpreet | B36: ='OUTSIDE GTA'!F270 -> 0 | C36: SUBCON | D36: 18 | E36: =B36*D36 -> 0
A37: Dikaran | B37: ='OUTSIDE GTA'!G270 -> 0 | C37: SUBCON | D37: 18 | E37: =B37*D37 -> 0
A39: Merland Park Cottages (12488 Loyalist Pkwy) TOTAL: | B39: =SUM(B32:B38) -> 0
A41: Tru by Hilton Bracebridge (320 Taylor Rd, Bracebridge)
A42: Armando | B42: ='OUTSIDE GTA'!C288 -> 0 | C42: SUBCON | D42: 16.65 | E42: =B42*D42 -> 0
A43: Shirley | B43: ='OUTSIDE GTA'!D288 -> 0 | C43: SUBCON | D43: 16.65 | E43: =B43*D43 -> 0
A45: Tru by Hilton Bracebridge (320 Taylor Rd, Bracebridge) | B45: =SUM(B41:B44) -> 0
A47: Home 2 by Hilton Woodstock (527 Lampman Pl)
A48: Menandro | B48: ='OUTSIDE GTA'!C35 -> 0 | C48: SUBCON | D48: 16.65 | E48: =B48*D48 -> 0 | F48: Home 2 by Hilton Woodstock (527 Lampman Pl)
A49: Asmita | B49: ='OUTSIDE GTA'!D107 -> 0 | C49: SUBCON | D49: 16.65 | E49: =B49*D49 -> 0 | F49: Chatham Kent
A50: Jonervin Agustin | B50: ='OUTSIDE GTA'!D35 -> 0 | C50: SUBCON | D50: 16.65 | E50: =B50*D50 -> 0 | F50: Home 2 by Hilton Woodstock (527 Lampman Pl)
A51: Dhruvkumar Harshadkumar Patel | B51: ='OUTSIDE GTA'!E35 -> 0 | C51: SUBCON | D51: 16.65 | E51: =B51*D51 -> 0 | F51: Home 2 by Hilton Woodstock (527 Lampman Pl)
A52: Sukhjivan Singh | B52: ='OUTSIDE GTA'!F35 -> 0 | C52: SUBCON | D52: 16.65 | E52: =B52*D52 -> 0 | F52: Home 2 by Hilton Woodstock (527 Lampman Pl)
...

Sheet Subcontractors
A1: ID | B1: Name | C1: Physical Address | D1: Interac Email Final | E1: Phone Number | F1: Alias | G1: Comment | H1: Mail or Pickup | I1: Column1 | J1: Column2
A2: MMJW0001 | B2: Danica Lauzon | C2: 1055A Forestwood Dr, Mississauga, ON L5C 2T8 | D2: lauzon_danica@yahoo.com | F2: Kenneth Abarra | G2: For Kenneth Abarra | H2: (PICK UP)
A3: MMJW0002 | B3: Noralyn Torre Camiguing | C3: 132 Holditch St, Bracebridge, ON P1L 1E7 | D3: jaysoncamiguing@gmail.com | E3: 164 744 8102 | G3: delayed salary | H3: #N/A
A4: MMJW0003 | B4: Anthony Baslot | C4: #204 565 Manchester Rd, Victoria, BC V8T 2N7 | D4: shielaann.baslot@yahoo.com | E4: 204 990 4956 | H4: #N/A
A5: MMJW0004 | B5: Michelle Curit | C5: 426 Huron St, Woodstock, ON N4S 7A7 | D5: michelle_sarabosing@yahoo.com | E5: 226 219 9521 | H5: #N/A
A6: MMJW0005 | B6: Herbert Centeno | C6: 110 Windermere Crescent, Woodstock, ON N4S 6T2 | D6: ellehci_m@yahoo.com.ph | E6: 226 228 4590 | G6: Forward to Michelle Enriquez | H6: E-transfer
A7: MMJW0006 | B7: Michelle Enriquez | C7: 110 Windermere Crescent, Woodstock, ON N4S 6T2 | D7: ellehci_m@yahoo.com.ph | E7: 226 228 4590 | F7: Myla, Herbert | G7: For Myla and Herbert Centeno | H7: E-transfer
A8: MMJW0007 | B8: Isaac Hunter | C8: 700 Chieftain Street Woodstock ON N4T 1S2 | D8: isaac.hunter2003@gmail.com | E8: 226 232 8065 | G8: i would prefer an etransfer and also i am in need of a paystub. | H8: #N/A
A9: MMJW0008 | B9: Armando C. Gabriola Jr. | C9: 1548 Purser St, London, ON N5V 5J4 | D9: armandogabriola2017@gmail.com | E9: 226 386 8343 | H9: #N/A
A10: MMJW0009 | B10: Jonervin Agustin | C10: 110 Windermere Crescent, Woodstock, ON N4S 6T2 | D10: jonervinagustin25@gmail.com | E10: 226 448 1652 | H10: **
A11: MMJW0010 | B11: Angel Lynne Ellan | C11: #1 579 Dundas St, Woodstock, ON N4S 1C9 | D11: angelgwapa28@gmail.com | E11: 226 503 7828 | G11: Interac pls | H11: E-transfer
A12: MMJW0011 | B12: Woddy Rivera | C12: 869 Adelaide St N, London, ON N5Y 2M2 | D12: epoi89091@gmail.com | E12: 226 582 5539 | H12: E-transfer
A13: MMJW0012 | B13: Gautam Gurung | C13: 1326 Fuller St, London, ON N5Y 4R2 | D13: thapasanti753@gmail.com | E13: 226 582 6757 | G13: Thanks | H13: 0
A14: MMJW0013 | B14: Ishpreet Kaur | C14: 14 Albright Rd, Brampton, ON L6X 5C8 | D14: ishpreetkaur28122004@gmail.com | E14: 226 753 1661 | H14: (PICK UP)
A15: MMJW0014 | B15: Kingsley Anugwo | C15: #B1 1279 Woodroffe Ave, Ottawa, ON K2C 2T7 | D15: anugwokingsley72@gmail.com | E15: 226 758 9937 | G15: Happy working with your organization, Thanks | H15: **
A16: MMJW0015 | B16: Zayrah Jusi | C16: 70 Hanes Road Huntsville ON P1H 1M3 | D16: zayrahjusi23@gmail.com | E16: 226 759 1522 | H16: #N/A
A17: MMJW0016 | B17: Elmer Delos Reyes | C17: 319 Dundas St, Woodstock, ON N4S 1B5 | D17: lmher03@yahoo.com | E17: 226 883 0592 | H17: E-transfer
A18: MMJW0017 | B18: Folashade Adekoya | C18: #2306 857 James St, Woodstock, ON N4S 8H5 | D18: ashandyawotungase@gmail.com | E18: 226 883 1763 | G18: Good | H18: **
A19: MMJW0018 | B19: Harpreet Harpreet | C19: 15 Graham St, Woodstock, ON N4S 6J5 | D19: jhinjerharpreet2@gmail.com | E19: 226 888 7747 | H19: 0
A20: MMJW0019 | B20: Meet Vanraj Mahida | C20: 257 Thorncrest Dr, Waterloo, ON N2L 4L2 | D20: meetmahida09500@gmail.com | E20: 226 899 7818 | H20: **
A21: MMJW0020 | B21: Daniel Ogunleye Bukoye | C21: 214 Speckled Alder Row, Ottawa, ON K2J 7G8 | D21: danielbukoye@gmail.com | E21: 226 966 5895 | F21: Daniel | G21: Non | H21: #N/A
A22: MMJW0021 | B22: Julie Jane Pamunag | C22: #11 511 Admiral Dr, London, ON N5V 4R4 | D22: jaepamunag95@gmail.com | E22: 226 977 9813 | G22: Kindly send the interac transfer with no notes. Please and thank you. Previous Address: 27A Empire St, London, ON N5Y 1G6 | H22: (PICK UP)
A23: MMJW0022 | B23: Julius Garcia | C23: #410 583 Mornington Ave, London, ON N5Y 3E9 | D23: jgarcia3327@gmail.com | E23: 226 998 1489 | H23: 0
A24: MMJW0023 | B24: Paul Jordan Untalan | C24: #715 621 Sheppard Ave E, Toronto, ON M2K 0G4 | D24: pauljordanuntalan@gmail.com | E24: 226-961-8796 | F24: Kapwa | H24: (PICK UP)
A25: MMJW0024 | B25: Anmol Saluja | C25: 2938 Oldcorn Pl, Victoria, BC V9B 2E9 | D25: anmolcan12@gmail.com | E25: 236 333 2065 | H25: #N/A
A26: MMJW0025 | B26: Heide Loraine Favor | C26: #2 853 Burdett Ave, Victoria, BC V8W 1B3 | D26: angelica.tadena@yahoo.com | E26: 236 638 6525 | G26: Interac details is through phone number please: 7786833737 | H26: 0
A27: MMJW0026 | B27: Henry Lopecillo | C27: 4111 24 Ave, Vernon, BC V1T 1M1 | D27: henrylopecillo@gmail.com | E27: 236 873 0036 | H27: #N/A
A28: MMJW0027 | B28: Henry Lopecillo Jr. | C28: 5300 25 Ave, Vernon, BC V1T 6Y2 | D28: henrylopecillo@gmail.com | E28: 236 873 0036 | H28: 0
A29: MMJW0028 | B29: Eduardo Dela Cruz | C29: BC V3R 7H7 | D29: khejdc1008@gmail.com | E29: 236 998 7645 | H29: #N/A
A30: MMJW0029 | B30: Sungcang Marvin | C30: 821 Hockley Ave, Victoria, BC V9B 0Z9 | D30: m.sungcang@yahoo.com | E30: 236-238-1372 | G30: NOTE : Void check provided but please I am prefer E transfer please | H30: E-transfer
A31: MMJW0030 | B31: Hazel Anne Masangkay | C31: 19 Newcastle Ct, Victoria, BC V9B 6V5 | D31: hazelsalvador.masangkay@gmail.com | E31: 236-638-8468 | H31: E-transfer
A32: MMJW0031 | B32: Muhammed Ibrahim | C32: 722 Spitfire St, Woodstock, ON N4T 0B1 | D32: muhad61191@gmail.com | E32: 249 885 5453 | H32: **
A33: MMJW0032 | B33: Carmela Ogena | C33: #521 1701 Cedar Hill Cross Rd, Victoria, BC V8P 2P9 | D33: vinperegrino@yahoo.com | E33: 250 885 1834 | G33: Please send it to my husband's account. | H33: 0
A34: MMJW0033 | B34: Jose Baldovino | C34: 3534 Redwood Ave., Victoria, BC V8P 4Z7 | D34: baldobaldovino1981@gmail.com | E34: 250 945 5840 | F34: Jose (Elk Lake) | G34: Thank you | H34: 0
A35: MMJW0034 | B35: Barkha Devi | C35: 3195 Balfour Ave, Victoria, BC V9A 1R9 | D35: barkhadevi015@gmail.com | E35: 250 986 1357 | H35: #N/A
A36: MMJW0035 | B36: Sheila Marie Cordon | C36: #304 844 Goldstream Ave, Langford, BC V9B 2X7 | D36: allancordon111969@gmail.com | E36: 250-532-1498 | G36: Holiday inn ekl lake time in 3:35 pm to 5:55 pm | H36: E-transfer
A37: MMJW0036 | B37: Ethel Ysabelle Delos Reyes | C37: #9 2105 Ave Van Horne, Montreal, QC H3S 1P3 | D37: ethelysabelle08@yahoo.com | E37: 263 881 4576 | H37: E-transfer
A38: MMJW0037 | B38: Prabin Pariyar | C38: 435 Upper Gage Ave. Hamilton, ON L8V 4H8 | D38: pariyarprabin1019@gmail.com | E38: 289 556 7245 | H38: **
A39: MMJW0038 | B39: Alish Shrestha | C39: 4653 Mcdougall Crescent, Niagara Falls, ON L2E 1B6 | D39: shresthaalish43@gmail.com | E39: 289 673 5618 | H39: E-transfer
A40: MMJW0039 | B40: Carlo Mallare | C40: 500 First Ave, Welland, ON L3C 1Z3 | D40: erlmediran@gmail.com / erlmediran@yahoo.com | E40: 289 681 5935 | G40: i haven't receive my pay for the June 30th i worked at Wyndamm Niagara Falls. Alternate email: erlmediran@yahoo.com | H40: #N/A
...

Sheet GTA
A5: Hyatt Place 5787 Hurontario St - Hyatt Place 5787 Hurontario St - Hyatt Place 5787 Hurontario St - Hyatt Place 5787 Hurontario St - Hyatt Place 5787 Hurontario St - Hyatt Place 5787 Hurontario St - Hyatt Place 5787 Hurontario St - Hyatt Place 5787 Hurontario St - Hyatt Place 5787 | BA5: ADJUSTMENT
B6: Jan | C6: Niloufar Shirvani | D6: Arman Thind | E6: Ernesto Jr. Gampon | F6: Gabriel Oloro Oloro | G6: Guilherme Augusto Coscarelli | H6: Inderjit Kaur | I6: Jan Choy Tee | J6: Joshua Jhon Emmanuel Sosa | K6: Komal Preet Kaur | L6: Madhur Manocha | M6: Mannat Badhan | N6: Naima | O6: Navneet Kaur.. | P6: Nuuradin Hassan | Q6: Olawale Onabanjo | R6: Olayiwola Emmanuel Olatide | S6: Osarenren Osamuyimen | T6: Rafael | U6: Ritesh Kumar | V6: Sapna Kumari | W6: Shifa Ibrahim | X6: Tolulope Opeyemi Gbenga-Olufeyisan | Y6: Ujunwa Jessica Okwuaka
A7: Sat | B7: 10 | ER7: Sat
A8: Sun | B8: 11 | ER8: Sun
A9: Mon | B9: 12 | ER9: Mon
A10: Tue | B10: 13 | ER10: Tue
A11: Wed | B11: 14 | ER11: Wed
A12: Thu | B12: 15 | ER12: Thu
A13: Fri | B13: 16 | C13: 7 | ER13: Fri
A14: Sat | B14: 17 | ER14: Sat
A15: Sun | B15: 18 | ER15: Sun
A16: Mon | B16: 19 | ER16: Mon
A17: Tue | B17: 20 | ER17: Tue
A18: Wed | B18: 21 | ER18: Wed
A19: Thu | B19: 22 | ER19: Thu
A20: Fri | B20: 23 | ER20: Fri
A21: Total | B21: =SUM(C21:EP21,ET21:EV21) -> 7 | C21: =SUM(C7:C20) -> 7 | D21: =SUM(D7:D20) -> 0 | E21: =SUM(E7:E20) -> 0 | F21: =SUM(F7:F20) -> 0 | G21: =SUM(G7:G20) -> 0 | H21: =SUM(H7:H20) -> 0 | I21: =SUM(I7:I20) -> 0 | J21: =SUM(J7:J20) -> 0 | ... EO21: =SUM(EO7:EO20) -> 0 | ER21: Total | ES21: =SUM(ET21:EV21) -> 0 | ET21: =SUM(ET7:ET20) -> 0 | EU21: =SUM(EU7:EU20) -> 0 | EV21: =SUM(EV7:EV20) -> 0
A22: =B22-B21 -> 444.5 | B22: 451.5
A23: HOLIDAY INN EXPRESS - RICHMOND HILL (10 East Pearce St.) | N23: ADJUSTMENT
B24: =B6 -> Jan | C24: Andrew Verches | D24: Paxson Intal Figueroa
A25: Sat | B25: =B7 -> 10 | D25: 7 | T25: Sat
A26: Sun | B26: =B8 -> 11 | C26: 13 | D26: 8 | T26: Sun
A27: Mon | B27: =B9 -> 12 | C27: 7 | T27: Mon
A28: Tue | B28: =B10 -> 13 | C28: 7 | D28: 7.5 | T28: Tue
A29: Wed | B29: =B11 -> 14 | C29: 7 | D29: 7.5 | T29: Wed
A30: Thu | B30: =B12 -> 15 | C30: 7 | D30: 7.5 | T30: Thu
A31: Fri | B31: =B13 -> 16 | D31: 7 | T31: Fri
A32: Sat | B32: =B14 -> 17 | C32: 13 | D32: 6 | T32: Sat
A33: Sun | B33: =B15 -> 18 | D33: 6 | T33: Sun
A34: Mon | B34: =B16 -> 19 | C34: 7 | T34: Mon
A35: Tue | B35: =B17 -> 20 | C35: 7 | T35: Tue
A36: Wed | B36: =B18 -> 21 | D36: 7 | T36: Wed
A37: Thu | B37: =B19 -> 22 | C37: 7 | D37: 8 | T37: Thu
A38: Fri | B38: =B20 -> 23 | C38: 7 | D38: 7 | T38: Fri
A39: Total | B39: =SUM(C39:S39)+U39 -> 160.5 | C39: =SUM(C26:C38) -> 82 | D39: =SUM(D25:D38) -> 78.5 | E39: =SUM(E25:E38) -> 0 | F39: =SUM(F25:F38) -> 0 | G39: =SUM(G25:G38) -> 0 | H39: =SUM(H25:H38) -> 0 | I39: =SUM(I25:I38) -> 0 | J39: =SUM(J25:J38) -> 0 | K39: =SUM(K25:K38) -> 0 | ... R39: =SUM(R25:R38) -> 0 | T39: Total | U39: =SUM(V39:X39) -> 0 | V39: =SUM(V25:V38) -> 0 | W39: =SUM(W25:W38) -> 0 | X39: =SUM(X25:X38) -> 0
A41: HOLIDAY INN EXPRESS (2125 NORTH SHERIDAN WAY MISSISSAUGA) | N41: ADJUSTMENT
B42: =B24 -> Jan | C42: Asmita Baral | D42: Rizalina | E42: Ansherina Orda | F42: Angelo | G42: Akin | H42: Baljit | I42: Bansi | J42: Pepito | K42: Kenneth | L42: Elo | M42: Komalpreet | N42: Merxedes MC Painting | O42: Namandeep | P42: Pardeep SS | Q42: Hameen | R42: Khristine | S42: Ranjit Singh | T42: Navneet | U42: Aldrin | V42: Aman | W42: Naneth Miro | X42: Cain | Y42: Chander | Z42: Esther | AA42: Cora | AB42: Giovanni Dulay | AC42: Gurpinder | AD42: Harpreet K | AE42: Harshdeep Singh | AF42: Ishpreet | AG42: Kamaljit | AH42: Karan Maheriya | AI42: Madhur | AJ42: Catherine MC Painting | AK42: Yohanny MC Painting | AL42: Simranjeet Kaur | AM42: Simranjot | AN42: Mark Jan | AO42: Mark V | AP42: Monia | AQ42: Myriam | AR42: Upasna | AS42: Damodar Dahal | AT42: Vivek
A43: Sat | B43: =B25 -> 10 | AV43: Sat
A44: Sun | B44: =B26 -> 11 | AV44: Sun
A45: Mon | B45: =B27 -> 12 | AV45: Mon
...

Sheet OUTSIDE GTA
A1: Manitou Springs Resort and Mineral Spa (302 MacLachlan Ave) | T1: ADJUSTMENT
B2: =GTA!B6 -> Jan | C2: Huberto | D2: Willy | P2: Menandro | Q2: Angel Ellan
A3: Sat | B3: =GTA!B7 -> 10 | U3: Sat | V3: 26
A4: Sun | B4: =GTA!B8 -> 11 | U4: Sun | V4: 27
A5: Mon | B5: =GTA!B9 -> 12 | U5: Mon | V5: 28
A6: Tue | B6: =GTA!B10 -> 13 | U6: Tue | V6: 29
A7: Wed | B7: =GTA!B11 -> 14 | U7: Wed | V7: 30
A8: Thu | B8: =GTA!B12 -> 15 | U8: Thu | V8: 31
A9: Fri | B9: =GTA!B13 -> 16 | U9: Fri | V9: 1
A10: Sat | B10: =GTA!B14 -> 17 | U10: Sat | V10: 2
A11: Sun | B11: =GTA!B15 -> 18 | U11: Sun | V11: 3
A12: Mon | B12: =GTA!B16 -> 19 | U12: Mon | V12: 4
A13: Tue | B13: =GTA!B17 -> 20 | U13: Tue | V13: 5
A14: Wed | B14: =GTA!B18 -> 21 | U14: Wed | V14: 6
... A16: Fri | B16: =GTA!B20 -> 23 | U16: Fri | V16: 8
A17: Total | B17: =SUM(C17:T17)+V17 -> 0 | C17: =SUM(C3:C16) -> 0 | D17: =SUM(D3:D16) -> 0 | F17: =SUM(F3:F16) -> 0 | G17: =SUM(G3:G16) -> 0 | H17: =SUM(H3:H16) -> 0 | I17: =SUM(I3:I16) -> 0 | J17: =SUM(J3:J16) -> 0 | K17: =SUM(K3:K16) -> 0 | L17: =SUM(L3:L16) -> 0 | M17: =SUM(M3:M16) -> 0 | ... T17: =SUM(T3:T16) -> 0 | U17: Total | V17: =SUM(W17:Y17) -> 0 | W17: =SUM(W3:W16) -> 0 | X17: =SUM(X3:X16) -> 0 | Y17: =SUM(Y3:Y16) -> 0
A19: Home 2 Hotel Woodstock (527 Lampman) | T19: ADJUSTMENT
B20: =B2 -> Jan | C20: Menandro | D20: Ruben | E20: Dhruv | F20: Sukhjivan | G20: Wilmar | H20: Harkirat | I20: Gagan | J20: Casey | K20: Emmanuel
A21: =A3 -> Sat | B21: =B3 -> 10 | T21: Sat
A22: =A4 -> Sun | B22: =B4 -> 11 | T22: Sun
A23: =A5 -> Mon | B23: =B5 -> 12 | T23: Mon
A24: =A6 -> Tue | B24: =B6 -> 13 | T24: Tue
A25: =A7 -> Wed | B25: =B7 -> 14 | T25: Wed
A26: =A8 -> Thu | B26: =B8 -> 15 | T26: Thu
A27: =A9 -> Fri | B27: =B9 -> 16 | T27: Fri
A28: =A10 -> Sat | B28: =B10 -> 17 | T28: Sat
A29: =A11 -> Sun | B29: =B11 -> 18 | T29: Sun
A30: =A12 -> Mon | B30: =B12 -> 19 | T30: Mon
A31: =A13 -> Tue | B31: =B13 -> 20 | T31: Tue
A32: =A14 -> Wed | B32: =B14 -> 21 | T32: Wed
... A34: =A16 -> Fri | B34: =B16 -> 23 | T34: Fri
A35: Total | B35: =SUM(C35:S35)+U35 -> 0 | C35: =SUM(C21:C34) -> 0 | D35: =SUM(D21:D34) -> 0 | E35: =SUM(E21:E34) -> 0 | F35: =SUM(F21:F34) -> 0 | G35: =SUM(G21:G34) -> 0 | H35: =SUM(H21:H34) -> 0 | I35: =SUM(I21:I34) -> 0 | J35: =SUM(J21:J34) -> 0 | ... S35: =SUM(S21:S34) -> 0 | T35: Total | U35: =SUM(V35:X35) -> 0 | V35: =SUM(V21:V34) -> 0 | W35: =SUM(W21:W34) -> 0 | X35: =SUM(X21:X34) -> 0
A37: Spark by Hilton Woodstock | T37: ADJUSTMENT
B38: October | C38: Veronica | D38: Adejumo | E38: Dianne G | F38: Dionisio | G38: Elvira D | H38: Balvir | I38: Casey | J38: Isaac | K38: Joseph | L38: Kafila | M38: Jennifer | N38: Susan | O38: Gautam | P38: Harkirat | Q38: Chali | R38: Voltair J | S38: Julius G | T38: Harpreet2x | U38: Parimal | V38: Fola | W38: Sivakumar Vinoth | X38: Nishal | Y38: Gurpreet K | Z38: Manpreet S | AA38: Jonervin Agustin | AB38: Elmer Delosreyes | AC38: Woddy
A39: Sat | B39: 4 | AE39: Sat
A40: Sun | B40: 5 | AE40: Sun
A41: Mon | B41: 6 | AE41: Mon
A42: Tue | B42: 7 | AE42: Tue
A43: Wed | B43: 8 | AE43: Wed
A44: Thu | B44: 9 | AE44: Thu
...

Sheet OTTAWA
A2: BEST WESTERN PLUS OTTAWA (1876 ROBERTSON RD, OTTAWA) | T2: ADJUSTMENT
B3: August - Sept | C3: Binta | D3: Abdulahi | E3: Bernard | F3: Brenda | G3: Carive | H3: Claudine | I3: Clein | J3: Collins Darko Nimako | K3: Christian Izuchukwu Osoagba | L3: Daisy Jerono Cheboswony | M3: Daniel Aboagye | N3: Daniela | O3: David Shedrack | P3: Douglas (HP) | Q3: Elvera | R3: Gary Maintenance | S3: Ivy | T3: Elsie Ndobegang Zinkeng | U3: Farel Manirakiza | V3: Fatouma | W3: Frank | X3: Freda | Y3: Flor | Z3: Hannah | AA3: Hargor Roberto Ninziza | AB3: Hursulla Camara Da Rocha (Front Desk) | AC3: Imaculee | AD3: Rita | AE3: Joshua F/O | AF3: Julien Vincent | AG3: Jordan | AH3: Ibrahim Adebayo | AI3: Ibrahim Kamaru | AJ3: James | AK3: Nick | AL3: Ilka Ingabire Bukuru | AM3: Isha Jallow | AN3: Manuela Doloresse Njikam Nzeket | AO3: Nancy Andong | AP3: Nonette Teta Shenge | AQ3: Manuella | AR3: Nshimirimana Carine | AS3: Olga | AT3: Paxella | AU3: Kevine | AV3: Rachel | AW3: Regine | AX3: Rehoboth Byiringiro | AY3: Rochell Ann Magtangobe Anne | AZ3: Rosette | BA3: Sarah Nyanduko | BB3: Sarah Ishimwe | BC3: Sahi | BD3: Simon | BE3: Safia Benafsha | BF3: Sofoa | BG3: Sodimu | BH3: Sylvester | BI3: William Gateru Ngure | BJ3: Yasin | BK3: Omowunmi Samuel | BL3: Farel Manirakiza (M) | BN3: Sat | BO3: SeptOct | BP3: Hursulla
A4: Sat | B4: 23 | BN4: Sat | BO4: 21
A5: Sun | B5: 24 | BM5: =BM13-BM12 -> 0 | BN5: Sun | BO5: 22
A6: Mon | B6: 25 | BN6: Mon | BO6: 23
A7: Tue | B7: 26 | BN7: Tue | BO7: 24
A8: Wed | B8: 27 | BN8: Wed | BO8: 25
A9: Thu | B9: 28 | BN9: Thu | BO9: 26
A10: Fri | B10: 29 | BN10: Fri | BO10: 27
A11: Sat | B11: 30 | BN11: Sat | BO11: 28
A12: Sun | B12: 31 | BM12: =SUM(C6:BL12) -> 0 | BN12: Sun | BO12: 29
A13: Mon | B13: 1 | BM13: =SUM(C4:BL12) -> 0 | BN13: Mon | BO13: 30 | BS13: =SUM(C13:BL13) -> 0
A14: Tue | B14: 2 | BN14: Tue | BO14: 1 | BS14: =SUM(C14:BL14) -> 0
A15: Wed | B15: 3 | BN15: Wed | BO15: 2 | BS15: =SUM(C15:BL15) -> 0
A16: Thu | B16: 4 | BN16: Thu | BO16: 3 | BS16: =SUM(C16:BL16) -> 0
A17: Fri | B17: 5 | BM17: =SUM(C13:BL17) -> 0 | BN17: Fri | BO17: 4 | BS17: =SUM(C17:BL17) -> 0
A18: Total | B18: =SUM(C18:BL18)+BO18 -> 0 | C18: =SUM(C4:C17) -> 0 | D18: =SUM(D4:D17) -> 0 | E18: =SUM(E4:E17) -> 0 | F18: =SUM(F4:F17) -> 0 | G18: =SUM(G4:G17) -> 0 | H18: =SUM(H4:H17) -> 0 | I18: =SUM(I4:I17) -> 0 | J18: =SUM(J4:J17) -> 0 | ... BL18: =SUM(BL4:BL17) -> 0 | BN18: Total | BO18: =SUM(BP18:BR18) -> 0 | BP18: =SUM(BP3:BP17) -> 0 | BQ18: =SUM(BQ3:BQ17) -> 0 | BR18: =SUM(BR3:BR17) -> 0
A20: DAYS INN OTTAWA WEST (350 MOODIE DR, OTTAWA)
B21: =B3 -> August - Sept | C21: Abidemi Tawakalit Olaore | D21: Abdulasiz | E21: Audriel | F21: Azeez Abefe | G21: Doly Tatchou Djikemi | H21: Amado | I21: Binta | J21: Brenda | K21: Carive | L21: Claudine | M21: Cleine | N21: Cleopatra | O21: Christian Izuchukwu Osoagba | P21: Christopher | Q21: Daniela | R21: Deborah | S21: Delphine | T21: Elsie Ndobegang Zinkeng | U21: Emily | V21: Enny | W21: Esther Suubi | X21: Eunice Ndinda Sammy | Y21: Fannie | Z21: Fatouma | AA21: Freda | AB21: Flor | AC21: Hannah | AD21: Safia Benafsha | AE21: Gary | AF21: Hargor Roberto Ninziza | AG21: Sunshine | AH21: Ibrahim Kamaru | AI21: Ibrahim Adebayo | AJ21: Ilona Diandra Igiraneza | AK21: Isha Touray | AL21: Ishwori | AM21: Jandira Vissolela Pedro da Costa E | AN21: Jasmine | AO21: Julien | AP21: Kevine | AQ21: Khaled Rugamba | AR21: Grace | AS21: Ivy | AT21: Laurie | AU21: Lawrencia | AV21: Marie | AW21: Manuela Doloresse Njikam Nzeket | AX21: Mbazumutima Dionne | AY21: Nafisa Akter | AZ21: Nancy Andong | BA21: Nelly | BB21: Nick | BC21: Njong Precious Eghah | BD21: Noela | BE21: Nonette Teta Shenge | BF21: Nshimirimana Carine | BG21: Nyinawase Merveille | BH21: Ojo | BI21: Olave Akundwe | BJ21: Olga Uwikunze | BK21: Onuchukwu Chidera | BL21: Oyebola Oladoyin | BM21: Pascaline | BN21: Pierre | BO21: Paxella Mizero | BP21: Pedro Mago Sendon | BQ21: Rehoboth Byiringiro | BR21: Rochell Ann Magtangobe | BS21: Roxette | BT21: Sarah Ishimwe | BU21: Simon Waweru | BV21: Sofoa | BW21: Sohail Mohammed Abdul | BX21: Stella | BY21: Tandi Suwaneh | BZ21: Ugochukwu | CA21: Vaida Awuor Ouma | CB21: Vanessa | CC21: Wumni | CD21: Yasin | CE21: Yvonne Wanjiru (HK) | CF21: Yvonne Wanjiru (SV) | CG21: Zita Charone Igihozo | CH21: Nataliia | CI21: Anna | CJ21: Imaculee | CK21: Daniel | CL21: Isaac | CM21: Divya | CN21: Abdula | CO21: Diego | CU21: July | CV21: Nataliia
A22: Sat | B22: =B4 -> 23 | CT22: Sat | CU22: 12
A23: Sun | B23: =B5 -> 24 | CT23: Sun | CU23: 13
A24: Mon | B24: =B6 -> 25 | CT24: Mon | CU24: 14
A25: Tue | B25: =B7 -> 26 | CT25: Tue | CU25: 15
A26: Wed | B26: =B8 -> 27 | CT26: Wed | CU26: 16
A27: Thu | B27: =B9 -> 28 | CT27: Thu | CU27: 17
A28: Fri | B28: =B10 -> 29 | CR28: =SUM(C22:CQ28) -> 0 | CT28: Fri | CU28: 18
A29: Sat | B29: =B11 -> 30 | CT29: Sat | CU29: 19
A30: Sun | B30: =B12 -> 31 | CT30: Sun | CU30: 20
A31: Mon | B31: =B13 -> 1 | CT31: Mon | CU31: 21
A32: Tue | B32: =B14 -> 2 | CT32: Tue | CU32: 22
A33: Wed | B33: =B15 -> 3 | CT33: Wed | CU33: 23
A34: Thu | B34: =B16 -> 4 | CT34: Thu | CU34: 24
A35: Fri | B35: =B17 -> 5 | CR35: =SUM(C29:CQ35) -> 0 | CT35: Fri | CU35: 25
A36: Total | B36: =SUM(C36:CP36) -> 0 | C36: =SUM(C22:C35) -> 0 | D36: =SUM(D22:D35) -> 0 | E36: =SUM(E22:E35) -> 0 | F36: =SUM(F22:F35) -> 0 | G36: =SUM(G22:G35) -> 0 | H36: =SUM(H22:H35) -> 0 | I36: =SUM(I22:I35) -> 0 | J36: =SUM(J22:J35) -> 0 | ... CP36: =SUM(CP22:CP35) -> 0 | CT36: Total | CU36: =SUM(CV36:GI36)+GN35 -> 0 | CV36: =SUM(CV22:CV35) -> 0 | CW36: =SUM(CW22:CW35) -> 0 | CX36: =SUM(CX22:CX35) -> 0
C37: =SUM(C29:C35) -> 0 | D37: =SUM(D29:D35) -> 0 | E37: =SUM(E29:E35) -> 0 | F37: =SUM(F29:F35) -> 0 | G37: =SUM(G29:G35) -> 0 | H37: =SUM(H29:H35) -> 0 | I37: =SUM(I29:I35) -> 0 | J37: =SUM(J29:J35) -> 0 | ... CP37: =SUM(CP29:CP35) -> 0 | CR37: =CR28+CR35 -> 0
A38: DAYS INN OTTAWA DOWNTOWN (319 RIDEAU ST, OTTAWA)
B39: =B21 -> August - Sept | C39: Connex | D39: Eunice | E39: Vanessa | F39: Etienne
A40: Sat | B40: =B22 -> 23
A41: Sun | B41: =B23 -> 24
A42: Mon | B42: =B24 -> 25
...

Sheet SUBCON - BC
A1: PAY PERIOD November 15 - 28, 2025 | B1: HOURS | C1: TYPE | D1: RATE | E1: TOTAL | Z1: =IFERROR( DATEVALUE( MID(A1,12,FIND("-",A1)-12) & ", " & RIGHT(A1,4) ), "") -> 45976
A2: Holiday Inn Elk Lake Victoria BC (4670 Elk Lake Drive) | Z2: {=_xlfn.LET( _xlpm.hdr, TRIM(A1), _xlpm.yr, TRIM(RIGHT(_xlpm.hdr,4)), _xlpm.body, TRIM(MID(_xlpm.hdr, 12, FIND(",", _xlpm.hdr) - 12)), _xlpm.startPart, TRIM(LEFT(_xlpm.body, FIND("-", _xlpm.body) - 1)), _xlpm.endRaw, TRIM(MID(_xlpm.body, FIND("-", _xlpm.body) + 1, 999)), _xlpm.months, {"January","February","March","April","May","June","July","August","September","October","November","December"}, _xlpm.hasMonth, SUM(--ISNUMBER(SEARCH(_xlpm.months, _xlpm.endRaw))), _xlpm.endPart, IF(_xlpm.hasMonth>0, _xlpm.endRaw, LEFT(_xlpm.startPart, FIND(" ", _xlpm.startPart & " ") - 1) & " " & _xlpm.endRaw), _xlpm.result, IFERROR(DATEVALUE(_xlpm.endPart & ", " & _xlpm.yr), ""), _xlpm.result )} -> 45989
A3: Aljhon | B3: {=IF((INDEX('British Columbia'!$C$18:$Z$18,ROW(A1)))=0,"",(INDEX('British Columbia'!$C$18:$Z$18,ROW(A1))))} | C3: SUBCON | D3: 16.65 | E3: =IF(B3="", 0, B3*D3) -> 0
A4: Anmol | B4: {=IF((INDEX('British Columbia'!$C$18:$Z$18,ROW(A2)))=0,"",(INDEX('British Columbia'!$C$18:$Z$18,ROW(A2))))} | C4: SUBCON | D4: 17 | E4: =IF(B4="", 0, B4*D4) -> 0
A5: Barkha | C5: SUBCON | D5: 17 | E5: =IF(B5="", 0, B5*D5) -> 0
A6: Emily | C6: SUBCON | D6: 17 | E6: =IF(B6="", 0, B6*D6) -> 0
A7: Harsh Kumar Sharma | C7: SUBCON | D7: 17 | E7: =IF(B7="", 0, B7*D7) -> 0
A8: Heide FD | C8: SUBCON | D8: 18 | E8: =IF(B8="", 0, B8*D8) -> 0
A9: Heide HK | C9: SUBCON | D9: 17 | E9: =IF(B9="", 0, B9*D9) -> 0
A10: Mirzi Lisa Pangan | B10: ='British Columbia'!J19 -> 23.5 | C10: SUBCON | D10: 17 | E10: =IF(B10="", 0, B10*D10) -> 399.5
A11: Jean Martin Junio (JM) | B11: ='British Columbia'!K19 -> 29 | C11: SUBCON | D11: 17 | E11: =IF(B11="", 0, B11*D11) -> 493
A12: Antonio | B12: ='British Columbia'!L19 -> 13 | C12: SUBCON | D12: 17 | E12: =IF(B12="", 0, B12*D12) -> 221
A13: Rolyn | B13: {=IF((INDEX('British Columbia'!$C$18:$Z$18,ROW(A11)))=0,"",(INDEX('British Columbia'!$C$18:$Z$18,ROW(A11))))} | C13: SUBCON | D13: 17 | E13: =IF(B13="", 0, B13*D13) -> 0
E14: =SUM(E6:E11) -> 892.5 | I14: BEST WESTERN PLUS (38 ESTATE DR, SCARBOROUGH)
A15: Holiday Inn Elk Lake Victoria BC (4670 Elk Lake Drive) TOTAL: | B15: =SUM(B3:B14) -> 65.5
I16: COURTYARD MISSISSAUGA WEST (290 DERRY ROAD W)
I17: COURTYARD MISSISSAUGA WEST (290 DERRY ROAD W)
A18: Holiday Inn Express & Suites Victoria - Colwood (318 Wale Rd)
A19: Aljhon Galgo | C19: SUBCON | D19: 17 | E19: =IF(B19="", 0, B19*D19) -> 0
A20: Barkha | B20: {=IF((INDEX('British Columbia'!$C$37:$Z$37,ROW(A2)))=0,"",(INDEX('British Columbia'!$C$37:$Z$37,ROW(A2))))} | C20: SUBCON | D20: 17 | E20: =IF(B20="", 0, B20*D20) -> 0
A21: Emily | C21: SUBCON | D21: 17 | E21: =IF(B21="", 0, B21*D21) -> 0
A22: Hazel | C22: SUBCON | D22: 17 | E22: =IF(B22="", 0, B22*D22) -> 0
A23: Heide FD | C23: SUBCON | D23: 18 | E23: =B23*D23 -> 0
A24: Jashan | C24: SUBCON | D24: 17 | E24: =IF(B24="", 0, B24*D24) -> 0
A25: Mar | C25: SUBCON | D25: 17 | E25: =IF(B25="", 0, B25*D25) -> 0
A26: Neeru | C26: SUBCON | D26: 17 | E26: =IF(B26="", 0, B26*D26) -> 0
A27: Marvin | C27: SUBCON | D27: 17 | E27: =IF(B27="", 0, B27*D27) -> 0
A28: Pedro Saluta Calvar | B28: {=IF((INDEX('British Columbia'!$C$37:$Z$37,ROW(A10)))=0,"",(INDEX('British Columbia'!$C$37:$Z$37,ROW(A10))))} | C28: SUBCON | D28: 17 | E28: =IF(B28="", 0, B28*D28) -> 0
A29: Sheila | C29: SUBCON | D29: 17 | E29: =IF(B29="", 0, B29*D29) -> 0
A30: Simrat | B30: {=IF((INDEX('British Columbia'!$C$37:$Z$37,ROW(A12)))=0,"",(INDEX('British Columbia'!$C$37:$Z$37,ROW(A12))))} | C30: SUBCON | D30: 17 | E30: =IF(B30="", 0, B30*D30) -> 0 | F30: =B32+B53+B15 -> 65.5
I31: BEST WESTERN PLUS (38 ESTATE DR, SCARBOROUGH)
A32: Holiday Inn Express & Suites Victoria - Colwood (318 Wale Rd) | B32: =SUM(B19:B31) -> 0
I33: COURTYARD MISSISSAUGA WEST (290 DERRY ROAD W)
I34: COURTYARD MISSISSAUGA WEST (290 DERRY ROAD W)
A35: Motel 6 Saanichton Victoria Airport BC (2401 Mt Newton Cross Rd)
A36: Aljhon | C36: SUBCON | D36: 17 | E36: =B36*D36 -> 0
A37: Pedro Saluta Calvar | C37: SUBCON | D37: 17 | E37: =B37*D37 -> 0
A38: Mirzi | C38: SUBCON | D38: 17 | E38: =B38*D38 -> 0
A39: JM | C39: SUBCON | D39: 17 | E39: =B39*D39 -> 0
A40: Haider | C40: SUBCON | D40: 18 | E40: =B40*D40 -> 0
...

Sheet British Columbia
A1: Holiday Inn Elk Lake Victoria BC (4670 Elk Lake) | U1: ADJUSTMENT
B2: Jan | C2: Aljhon | D2: Anmol | E2: Barkha | F2: Emily | G2: Harsh | H2: Heide FD | I2: Heide HK | J2: Mirzi | K2: JM | L2: Antonio | M2: Rolyn | V2: July | W2: Heide FD | X2: Heide HK
A3: Mon | B3: 12 | U3: Mon | V3: 14 | AA3: =_xlfn.LET( _xlpm.monthText, $B$2, _xlpm.dayNum, B3, _xlpm.prevDay, IF(ROW()=3, 0, B2), _xlpm.month1, TRIM(LEFT(_xlpm.monthText, FIND("-", _xlpm.monthText & "-") - 1)), _xlpm.month2, IFERROR(TRIM(MID(_xlpm.monthText, FIND("-", _xlpm.monthText & "-") + 1, 99)), ""), _xlpm.useMonth, IF( _xlpm.month2 = "", _xlpm.month1, IF(ROW()=3, _xlpm.month1, IF(_xlpm.dayNum < _xlpm.prevDay, _xlpm.month2, _xlpm.month1)) ), IFERROR(DATEVALUE(_xlpm.useMonth & " " & _xlpm.dayNum & ", " & 2025), "") ) -> 45669 | AD3: =5.5+6+7.5+7.5+7.5+6.75+4.45+7.25+6.25+8 -> 66.7
A4: Tue | B4: 13 | K4: 5 | U4: Tue | V4: 15 | AA4: =_xlfn.LET( _xlpm.monthText, $B$2, _xlpm.dayNum, B4, _xlpm.prevDay, IF(ROW()=3, 0, B3), _xlpm.month1, TRIM(LEFT(_xlpm.monthText, FIND("-", _xlpm.monthText & "-") - 1)), _xlpm.month2, IFERROR(TRIM(MID(_xlpm.monthText, FIND("-", _xlpm.monthText & "-") + 1, 99)), ""), _xlpm.useMonth, IF( _xlpm.month2 = "", _xlpm.month1, IF(ROW()=3, _xlpm.month1, IF(_xlpm.dayNum < _xlpm.prevDay, _xlpm.month2, _xlpm.month1)) ), IFERROR(DATEVALUE(_xlpm.useMonth & " " & _xlpm.dayNum & ", " & 2025), "") ) -> 45670
A5: Wed | B5: 14 | J5: 4.5 | K5: 5 | U5: Wed | V5: 16 | AA5: =_xlfn.LET( _xlpm.monthText, $B$2, _xlpm.dayNum, B5, _xlpm.prevDay, IF(ROW()=3, 0, B4), _xlpm.month1, TRIM(LEFT(_xlpm.monthText, FIND("-", _xlpm.monthText & "-") - 1)), _xlpm.month2, IFERROR(TRIM(MID(_xlpm.monthText, FIND("-", _xlpm.monthText & "-") + 1, 99)), ""), _xlpm.useMonth, IF( _xlpm.month2 = "", _xlpm.month1, IF(ROW()=3, _xlpm.month1, IF(_xlpm.dayNum < _xlpm.prevDay, _xlpm.month2, _xlpm.month1)) ), IFERROR(DATEVALUE(_xlpm.useMonth & " " & _xlpm.dayNum & ", " & 2025), "") ) -> 45671
A6: Thu | B6: 15 | J6: 5.5 | K6: 5.5 | U6: Thu | V6: 17 | AA6: =_xlfn.LET( _xlpm.monthText, $B$2, _xlpm.dayNum, B6, _xlpm.prevDay, IF(ROW()=3, 0, B5), _xlpm.month1, TRIM(LEFT(_xlpm.monthText, FIND("-", _xlpm.monthText & "-") - 1)), _xlpm.month2, IFERROR(TRIM(MID(_xlpm.monthText, FIND("-", _xlpm.monthText & "-") + 1, 99)), ""), _xlpm.useMonth, IF( _xlpm.month2 = "", _xlpm.month1, IF(ROW()=3, _xlpm.month1, IF(_xlpm.dayNum < _xlpm.prevDay, _xlpm.month2, _xlpm.month1)) ), IFERROR(DATEVALUE(_xlpm.useMonth & " " & _xlpm.dayNum & ", " & 2025), "") ) -> 45672
A7: Fri | B7: 16 | J7: 5.5 | K7: 5.5 | U7: Fri | V7: 18 | AA7: =_xlfn.LET( _xlpm.monthText, $B$2, _xlpm.dayNum, B7, _xlpm.prevDay, IF(ROW()=3, 0, B6), _xlpm.month1, TRIM(LEFT(_xlpm.monthText, FIND("-", _xlpm.monthText & "-") - 1)), _xlpm.month2, IFERROR(TRIM(MID(_xlpm.monthText, FIND("-", _xlpm.monthText & "-") + 1, 99)), ""), _xlpm.useMonth, IF( _xlpm.month2 = "", _xlpm.month1, IF(ROW()=3, _xlpm.month1, IF(_xlpm.dayNum < _xlpm.prevDay, _xlpm.month2, _xlpm.month1)) ), IFERROR(DATEVALUE(_xlpm.useMonth & " " & _xlpm.dayNum & ", " & 2025), "") ) -> 45673
A8: Sat | B8: 17 | K8: 4 | U8: Sat | V8: 19 | AA8: =_xlfn.LET( _xlpm.monthText, $B$2, _xlpm.dayNum, B8, _xlpm.prevDay, IF(ROW()=3, 0, B7), _xlpm.month1, TRIM(LEFT(_xlpm.monthText, FIND("-", _xlpm.monthText & "-") - 1)), _xlpm.month2, IFERROR(TRIM(MID(_xlpm.monthText, FIND("-", _xlpm.monthText & "-") + 1, 99)), ""), _xlpm.useMonth, IF( _xlpm.month2 = "", _xlpm.month1, IF(ROW()=3, _xlpm.month1, IF(_xlpm.dayNum < _xlpm.prevDay, _xlpm.month2, _xlpm.month1)) ), IFERROR(DATEVALUE(_xlpm.useMonth & " " & _xlpm.dayNum & ", " & 2025), "") ) -> 45674
A9: Sun | B9: 18 | K9: 5.5 | T9: =SUM(C3:S9) -> 46 | U9: Sun | V9: 20 | AA9: =_xlfn.LET( _xlpm.monthText, $B$2, _xlpm.dayNum, B9, _xlpm.prevDay, IF(ROW()=3, 0, B8), _xlpm.month1, TRIM(LEFT(_xlpm.monthText, FIND("-", _xlpm.monthText & "-") - 1)), _xlpm.month2, IFERROR(TRIM(MID(_xlpm.monthText, FIND("-", _xlpm.monthText & "-") + 1, 99)), ""), _xlpm.useMonth, IF( _xlpm.month2 = "", _xlpm.month1, IF(ROW()=3, _xlpm.month1, IF(_xlpm.dayNum < _xlpm.prevDay, _xlpm.month2, _xlpm.month1)) ), IFERROR(DATEVALUE(_xlpm.useMonth & " " & _xlpm.dayNum & ", " & 2025), "") ) -> 45675
A10: Mon | B10: 19 | J10: 7 | U10: Mon | V10: 21 | AA10: =_xlfn.LET( _xlpm.monthText, $B$2, _xlpm.dayNum, B10, _xlpm.prevDay, IF(ROW()=3, 0, B9), _xlpm.month1, TRIM(LEFT(_xlpm.monthText, FIND("-", _xlpm.monthText & "-") - 1)), _xlpm.month2, IFERROR(TRIM(MID(_xlpm.monthText, FIND("-", _xlpm.monthText & "-") + 1, 99)), ""), _xlpm.useMonth, IF( _xlpm.month2 = "", _xlpm.month1, IF(ROW()=3, _xlpm.month1, IF(_xlpm.dayNum < _xlpm.prevDay, _xlpm.month2, _xlpm.month1)) ), IFERROR(DATEVALUE(_xlpm.useMonth & " " & _xlpm.dayNum & ", " & 2025), "") ) -> 45676
A11: Tue | B11: 20 | L11: 8 | U11: Tue | V11: 22 | AA11: =_xlfn.LET( _xlpm.monthText, $B$2, _xlpm.dayNum, B11, _xlpm.prevDay, IF(ROW()=3, 0, B10), _xlpm.month1, TRIM(LEFT(_xlpm.monthText, FIND("-", _xlpm.monthText & "-") - 1)), _xlpm.month2, IFERROR(TRIM(MID(_xlpm.monthText, FIND("-", _xlpm.monthText & "-") + 1, 99)), ""), _xlpm.useMonth, IF( _xlpm.month2 = "", _xlpm.month1, IF(ROW()=3, _xlpm.month1, IF(_xlpm.dayNum < _xlpm.prevDay, _xlpm.month2, _xlpm.month1)) ), IFERROR(DATEVALUE(_xlpm.useMonth & " " & _xlpm.dayNum & ", " & 2025), "") ) -> 45677
